Workbook
Name Inv_Cap: #REF!
Name NOPLAT: #REF!
Name One: #REF!
Name Products: #REF!
Name Rev: #REF!

Sheet Cover
B7: PayPal
B9: Leveraged Buyout Model
B11: =TODAY() -> 46208
B13: By: Tyler Spencer
B15: RETURNS BY SCENARIO | F15: VALUATION
B18: Scenario | C18: MOIC | D18: IRR | F18: Methodology | J18: Low | K18: High
B19: Best Case (Bull) | C19: 4.38 | D19: 0.343 | F19: DCF | J19: ='Summary Outputs'!M47 -> 54.894513 | K19: ='Summary Outputs'!O47 -> 66.060539
B20: Base Case | C20: 2.48 | D20: 0.199 | F20: Precedent Transactions | J20: ='Summary Outputs'!M48 -> 100.73201 | K20: ='Summary Outputs'!O48 -> 115.61964
B21: Worst Case (Bear) | C21: 0.97 | D21: -0.005 | F21: Comparable Companies | J21: ='Summary Outputs'!M49 -> 77.949123 | K21: ='Summary Outputs'!O49 -> 90.012909
B22: ="Currently running: ("&CHOOSE(Scenarios!$C$6,Scenarios!$B$10,Scenarios!$B$11,Scenarios!$B$12)&"): MOIC "&TEXT('LBO Returns'!$D$16,"0.00x")&", IRR "&TEXT('LBO Returns'!$E$16,"0.0%") -> Currently running: (Base Case): MOIC 2.48x, IRR 19.9% | F22: LBO Range | J22: ='Summary Outputs'!M50 -> 41.902774 | K22: ='Summary Outputs'!O50 -> 53.317619
F23: ="Currently running: ("&CHOOSE(Scenarios!$C$6,Scenarios!$B$10,Scenarios!$B$11,Scenarios!$B$12)&"): MOIC "&TEXT('LBO Returns'!$D$16,"0.00x")&", IRR "&TEXT('LBO Returns'!$E$16,"0.0%") -> Currently running: (Base Case): MOIC 2.48x, IRR 19.9%
B24: Investment Thesis | F24: ="Max sponsor bid for 15% IRR: "&TEXT(K22,"$0.00") -> Max sponsor bid for 15% IRR: $53.32
B25: =IF('LBO Returns'!$E$16>0.149,"Clears sponsor return hurdle","Below sponsor return hurdle") -> Clears sponsor return hurdle | F25: ="Max LBO price premium compared to current market: "&TEXT((K22/Assumptions!N7)-1,"0.0%") -> Max LBO price premium compared to current market: 17.3%
B26: =IF(Cover!K22<MIN(Cover!J19,Cover!J20,Cover!J21),"Market premium below threshold","Market premium clears threshold") -> Market premium below threshold

Sheet Summary Outputs
O1: ="CURRENTLY RUNNING: "&UPPER(CHOOSE(Scenarios!$C$6,Scenarios!B10,Scenarios!B11,Scenarios!B12))&" SCENARIO" -> CURRENTLY RUNNING: BASE CASE SCENARIO
B2: =Cover!B7 -> PayPal
B3: Summary Outputs
C5: ="SUMMARY VALUES FOR "&UPPER(CHOOSE(Scenarios!$C$6,Scenarios!B10,Scenarios!B11,Scenarios!B12))&" SCENARIO" -> SUMMARY VALUES FOR BASE CASE SCENARIO
K6: Projected
D7: ($ Millions) | F7: Trend | H7: =IS!E6 -> 2023 | I7: =IS!F6 -> 2024 | J7: =IS!G6 -> 2025 | K7: =IS!H6 -> 2026 | L7: =IS!I6 -> 2027 | M7: =IS!J6 -> 2028 | N7: =IS!K6 -> 2029 | O7: =IS!L6 -> 2030
D9: Income Statement Items
D11: Net Revenue | H11: =IS!E8 -> 29771 | I11: =IS!F8 -> 31797 | J11: =IS!G8 -> 33172 | K11: =IS!H8 -> 34315.686 | L11: =IS!I8 -> 35688.889 | M11: =IS!J8 -> 37318.556 | N11: =IS!K8 -> 39243.381 | O11: =IS!L8 -> 41267.006
D12: Growth | I12: =(I11/H11)-1 -> 0.068052803 | J12: =(J11/I11)-1 -> 0.043243073 | K12: =(K11/J11)-1 -> 0.034477453 | L12: =(L11/K11)-1 -> 0.04001676 | M12: =(M11/L11)-1 -> 0.045663156 | N12: =(N11/M11)-1 -> 0.05157824 | O12: =(O11/N11)-1 -> 0.051566007
D15: EBITDA | H15: =IS!E28 -> 6100 | I15: =IS!F28 -> 6357 | J15: =IS!G28 -> 7028 | K15: =IS!H28 -> 7146.835 | L15: =IS!I28 -> 7104.3207 | M15: =IS!J28 -> 7245.4198 | N15: =IS!K28 -> 7545.2307 | O15: =IS!L28 -> 7904.1752
D16: Margin | H16: =H15/H11 -> 0.20489738 | I16: =I15/I11 -> 0.19992452 | J16: =J15/J11 -> 0.21186543 | K16: =K15/K11 -> 0.20826729 | L16: =L15/L11 -> 0.19906254 | M16: =M15/M11 -> 0.19415059 | N16: =N15/N11 -> 0.1922676 | O16: =O15/O11 -> 0.1915374
D17: Growth | I17: =(I15/H15)-1 -> 0.042131148 | J17: =(J15/I15)-1 -> 0.10555293 | K17: =(K15/J15)-1 -> 0.016908788 | L17: =(L15/K15)-1 -> -0.0059486872 | M17: =(M15/L15)-1 -> 0.019861029 | N17: =(N15/M15)-1 -> 0.041379365 | O17: =(O15/N15)-1 -> 0.04757237
D20: Net Income | H20: =IS!E25 -> 4246 | I20: =IS!F25 -> 4147 | J20: =IS!G25 -> 5233 | K20: =IS!H25 -> 5255.3709 | L20: =IS!I25 -> 5168.7406 | M20: =IS!J25 -> 5227.7721 | N20: =IS!K25 -> 5453.3605 | O20: =IS!L25 -> 5705.2741
D21: Margin | H21: =H20/H11 -> 0.14262201 | I21: =I20/I11 -> 0.13042111 | J21: =J20/J11 -> 0.15775353 | K21: =K20/K11 -> 0.15314777 | L21: =L20/L11 -> 0.14482773 | M21: =M20/M11 -> 0.14008506 | N21: =N20/N11 -> 0.13896255 | O21: =O20/O11 -> 0.13825268
D22: Growth | I22: =(I20/H20)-1 -> -0.023316062 | J22: =(J20/I20)-1 -> 0.26187605 | K22: =(K20/J20)-1 -> 0.0042749697 | L22: =(L20/K20)-1 -> -0.016484142 | M22: =(M20/L20)-1 -> 0.011420852 | N22: =(N20/M20)-1 -> 0.043151933 | O22: =(O20/N20)-1 -> 0.046194191
D24: LBO Credit Statistics
D25: Total Debt | K25: ='LBO Debt Schedule'!H89 -> 26385.01 | L25: ='LBO Debt Schedule'!I89 -> 22348.578 | M25: ='LBO Debt Schedule'!J89 -> 18127.413 | N25: ='LBO Debt Schedule'!K89 -> 13587.376 | O25: ='LBO Debt Schedule'!L89 -> 8614.2824
D26: Net Debt | K26: ='LBO Debt Schedule'!H90 -> 25385.01 | L26: ='LBO Debt Schedule'!I90 -> 21348.578 | M26: ='LBO Debt Schedule'!J90 -> 17127.413 | N26: ='LBO Debt Schedule'!K90 -> 12587.376 | O26: ='LBO Debt Schedule'!L90 -> 7614.2824
D27: Gross Leverage | K27: ='LBO Debt Schedule'!H91 -> 3.6918454 | L27: ='LBO Debt Schedule'!I91 -> 3.1457727 | M27: ='LBO Debt Schedule'!J91 -> 2.5019134 | N27: ='LBO Debt Schedule'!K91 -> 1.80079 | O27: ='LBO Debt Schedule'!L91 -> 1.0898395
D28: Net Leverage | K28: ='LBO Debt Schedule'!H92 -> 3.5519234 | L28: ='LBO Debt Schedule'!I92 -> 3.0050133 | M28: ='LBO Debt Schedule'!J92 -> 2.3638952 | N28: ='LBO Debt Schedule'!K92 -> 1.668256 | O28: ='LBO Debt Schedule'!L92 -> 0.96332409
D29: Interest Coverage | K29: ='LBO Debt Schedule'!H93 -> 3.9472369 | L29: ='LBO Debt Schedule'!I93 -> 4.6524269 | M29: ='LBO Debt Schedule'!J93 -> 5.8134091 | N29: ='LBO Debt Schedule'!K93 -> 7.7362735 | O29: ='LBO Debt Schedule'!L93 -> 11.339523
C32: LBO EQUITY VALUE CREATION | K32: DCF VALUATION
C33: Component | H33: $mm
C35: Entry Equity | H35: =LBO!D48 -> 19244.94 | N35: Perpetuity | O35: EBITDA
C36: Change in EBITDA | H36: =('LBO Exit Valuation'!G8 - LBO!E10) * LBO!E22 -> 8065.2262 | K36: EV | N36: =DCF!C91 -> 55213.605 | O36: =DCF!D91 -> 53479.884
C37: Change in Multiple | H37: =('LBO Exit Valuation'!G7 - LBO!E22) * 'LBO Exit Valuation'!G8 -> 0 | K37: Net debt | N37: =DCF!C92 -> -3369 | O37: =DCF!D92 -> -3369
C38: Debt Paydown | H38: =(SUM(LBO!D43:D47) - ('LBO Debt Schedule'!L66)) -> 21769.718 | K38: Equity value | N38: =N36-N37 -> 58582.605 | O38: =O36-O37 -> 56848.884
C39: Less: Fees | H39: =-LBO!D37 -> -1364.94 | K39: Shares outstanding | N39: =DCF!C94 -> 952.421 | O39: =DCF!D94 -> 952.421
C40: Exit Equity | H40: ='LBO Exit Valuation'!G19 -> 47714.944 | K40: Equity value/ share | N40: =N38/N39 -> 61.509149 | O40: =O38/O39 -> 59.688818
C41: Check | H41: =SUM(H35:H39)-H40 -> 0
C43: VALUATION SUMMARY
L46: Methodology | M46: Low | N46: Difference | O46: High
C47: ="DCF Value at "&TEXT(DCF!D122,"0.0x")&"-"&TEXT(DCF!H122,"0.0x")&" Exit EBITDA Range at "&TEXT(DCF!C125,"0.0%")&" WACC" -> DCF Value at 6.0x-8.0x Exit EBITDA Range at 9.2% WACC | L47: DCF | M47: =DCF!D166 -> 54.894513 | N47: =O47-M47 -> 11.166026 | O47: =DCF!F166 -> 66.060539
C48: ="Implied precedent transaction value at "&TEXT(Precedents!F81,"0.0x")&"-"&TEXT(Precedents!E81,"0.0x")&" based on LTM EBITDA" -> Implied precedent transaction value at 13.7x-15.8x based on LTM EBITDA | L48: Precedents | M48: =Precedents!F87 -> 100.73201 | N48: =O48-M48 -> 14.88763 | O48: =Precedents!E87 -> 115.61964
C49: ="Implied comparable company value at "&TEXT(Comps!M48,"0.0x")&"-"&TEXT(Comps!M47,"0.0x")&" based on LTM EBITDA" -> Implied comparable company value at 10.5x-12.2x based on LTM EBITDA | L49: Comparables | M49: =Comps!M58 -> 77.949123 | N49: =O49-M49 -> 12.063786 | O49: =Comps!M64 -> 90.012909
C50: ="Offer value/share at "&TEXT('LBO Returns'!F25,"0.0%")&" - "&TEXT('LBO Returns'!I25,"0.0%")&" IRR" -> Offer value/share at 15.0% - 30.0% IRR | L50: LBO | M50: ='LBO Returns'!I28 -> 41.902774 | N50: =O50-M50 -> 11.414845 | O50: ='LBO Returns'!F28 -> 53.317619
C51: 52 Week Market High/Low | L51: 52 Wk Range | M51: 38.46 | N51: =O51-M51 -> 41.04 | O51: 79.5

Sheet Assumptions
N1: ="CURRENTLY RUNNING: "&UPPER(CHOOSE(Scenarios!$C$6,Scenarios!B10,Scenarios!B11,Scenarios!B12))&" SCENARIO" -> CURRENTLY RUNNING: BASE CASE SCENARIO
B2: =Cover!B7 -> PayPal
B3: Inputs and Assumptions
C5: GENERAL | J5: EQUITY
C7: - | D7: First year of forecast in financial model: | G7: 2026 | J7: Most Recent Stock Price | N7: 45.47
J8: Stock Price Date | N8: 46208
C9: - | D9: Three scenarios have been used for Total Payment Volume (TPV), | J9: Shares Outstanding 1/28/26 (in MM) | N9: 920.664
D10: Take Rate Compression, Other Value Added Services, Transaction | J10: LTM Average Share Price | N10: 58.49
D11: Expense, Transaction and Credit Losses, and Technology and | J11: Outstanding RSU's | N11: 31.757
D12: Development | J12: Dividend Per Share | N12: 0.56
C16: SCENARIO CASES | J16: REVENUE DRIVERS
C18: - | D18: The Total Payment Volume cases are as follows:
C19: Pricing Case | J19: Total Payment Volume Growth | N19: =Scenarios!H11 -> 0.06
C20: Base Case | E20: Research Forecast | J20: Take Rate Compression Year 1 | N20: =Scenarios!H14 -> -0.0004
C21: Best Case | F21: 0.02 | J21: Other Value-Added Services Growth | N21: =Scenarios!H20 -> 0.04
C22: Worst Case | F22: -0.02
C25: COSTS | J25: INTEREST RATES
C27: Driver
C28: Transaction Expenses | F28: % of TPV | H28: =Scenarios!H26 -> 0.0089 | J28: Interest earned on Cash balances: | N28: 0.03
C29: Transaction & Credit Losses | F29: % of TPV | H29: =Scenarios!H32 -> 0.00096 | J29: Interest rate on Bank Revolver:
C30: Customer Support & Operations | F30: % of rev | H30: 0.051 | J30: Interest rate on Senior Secured Term Debt: | N30: 0.039
C31: Sales & Marketing | F31: % of rev | H31: 0.069 | J31: Yield on customer balances: | N31: 0.032
C32: Technology & Development Growth | F32: % | H32: =Scenarios!H38 -> 0.03 | J32: Customer funds balance growth: | N32: 0.03
C33: General & Administrative | F33: % | H33: 0.02
C34: Stock-based compensation | F34: % of rev | H34: 0.034
C37: Capex & D&A | J37: TAXES
C39: Capital Expenditures | F39: % of rev | H39: 0.024 | J39: Tax rate assumed in the model: | N39: 0.21
C40: D&A | F40: % of capex
C42: Debt Repayment | J42: Circuit Breaker & Other
C44: Year | J44: Circuit Breaker | N44: OFF
D45: 2026 | F45: 10-K FY 2025 p. 105 | H45: 1397
D46: 2027 | F46: 10-K FY 2025 p. 105 | H46: 1075 | J46: Minimum cash of $1,000M assumes upstream distributions
D47: 2028 | F47: 10-K FY 2025 p. 105 | H47: 1137 | J47: from regulated subsidiaries are feasible; actual sweepable cash may
D48: 2029 | F48: 10-K FY 2025 p. 105 | H48: 1500 | J48: be lower due to money-transmitter licensing requirements at
D49: 2030 | F49: 10-K FY 2025 p. 105 | H49: 1000 | J49: PayPal, Inc. (FY2025 10-K pp. 10, 44).
C54: OTHER ASSUMPTIONS | H54: 2024 | I54: =H54+1 -> 2025 | J54: =I54+1 -> 2026 | K54: =J54+1 -> 2027 | L54: =K54+1 -> 2028 | M54: =L54+1 -> 2029 | N54: =M54+1 -> 2030
C57: Take Rate Compression | G57: % | J57: -0.0004 | K57: -0.0003 | L57: -0.0002 | M57: -0.0001 | N57: -0.0001
C59: Capital Expenditures | G59: MM | J59: =$H$39*'Revenue Build'!H11 -> 823.57647 | K59: =$H$39*'Revenue Build'!I11 -> 856.53333 | L59: =$H$39*'Revenue Build'!J11 -> 895.64534 | M59: =$H$39*'Revenue Build'!K11 -> 941.84115 | N59: =$H$39*'Revenue Build'!L11 -> 990.40814
C61: Income Tax
D62: Reduction in EBT for timing differences | G62: MM | H62: =231/$N$39 -> 1100 | I62: =217/$N$39 -> 1033.3333 | J62: =J65/$N$39 -> 1144.4047 | K62: =K65/$N$39 -> 759.74868 | L62: =L65/$N$39 -> 504.38283 | M62: =M65/$N$39 -> 334.85025 | N62: =N65/$N$39 -> 222.30077
...

Sheet Scenarios
L1: ="CURRENTLY RUNNING: "&UPPER(CHOOSE(Scenarios!$C$6,Scenarios!B10,Scenarios!B11,Scenarios!B12))&" SCENARIO" -> CURRENTLY RUNNING: BASE CASE SCENARIO
B2: =Cover!B7 -> PayPal
B3: Scenario Analysis
H5: Projected
B6: Scenario Switch | C6: 2 | H6: ='Equity Schedule'!H6 -> 2026 | I6: ='Equity Schedule'!I6 -> 2027 | J6: ='Equity Schedule'!J6 -> 2028 | K6: ='Equity Schedule'!K6 -> 2029 | L6: ='Equity Schedule'!L6 -> 2030
B8: Total Payment Volume (TPV) | H8: =CHOOSE($C$6,H10,H11,H12) -> 0.06 | I8: =CHOOSE($C$6,I10,I11,I12) -> 0.06 | J8: =CHOOSE($C$6,J10,J11,J12) -> 0.06 | K8: =CHOOSE($C$6,K10,K11,K12) -> 0.06 | L8: =CHOOSE($C$6,L10,L11,L12) -> 0.06
B10: Best Case | C10: 0.02 | H10: =H11+$C$10 -> 0.08 | I10: =I11+$C$10 -> 0.08 | J10: =J11+$C$10 -> 0.08 | K10: =K11+$C$10 -> 0.08 | L10: =L11+$C$10 -> 0.08
B11: Base Case | H11: 0.06 | I11: 0.06 | J11: 0.06 | K11: 0.06 | L11: 0.06
B12: Worst Case | C12: -0.02 | H12: =H11+$C$12 -> 0.04 | I12: =I11+$C$12 -> 0.04 | J12: =J11+$C$12 -> 0.04 | K12: =K11+$C$12 -> 0.04 | L12: =L11+$C$12 -> 0.04
B14: Take Rate Compression | H14: =CHOOSE($C$6,H16,H17,H18) -> -0.0004 | I14: =CHOOSE($C$6,I16,I17,I18) -> -0.0003 | J14: =CHOOSE($C$6,J16,J17,J18) -> -0.0002 | K14: =CHOOSE($C$6,K16,K17,K18) -> -0.0001 | L14: =CHOOSE($C$6,L16,L17,L18) -> -0.0001
B16: Best Case | C16: 5e-05 | H16: =H17+$C$16 -> -0.00035 | I16: =I17+$C$16 -> -0.00025 | J16: =J17+$C$16 -> -0.00015 | K16: =K17+$C$16 -> -5e-05 | L16: =L17+$C$16 -> -5e-05
B17: Base Case | H17: =Assumptions!J57 -> -0.0004 | I17: =Assumptions!K57 -> -0.0003 | J17: =Assumptions!L57 -> -0.0002 | K17: =Assumptions!M57 -> -0.0001 | L17: =Assumptions!N57 -> -0.0001
B18: Worst Case | C18: -5e-05 | H18: =H17+$C$18 -> -0.00045 | I18: =I17+$C$18 -> -0.00035 | J18: =J17+$C$18 -> -0.00025 | K18: =K17+$C$18 -> -0.00015 | L18: =L17+$C$18 -> -0.00015
B20: Other Value-Added Services, ex-interest | H20: =CHOOSE($C$6,H22,H23,H24) -> 0.04 | I20: =CHOOSE($C$6,I22,I23,I24) -> 0.04 | J20: =CHOOSE($C$6,J22,J23,J24) -> 0.04 | K20: =CHOOSE($C$6,K22,K23,K24) -> 0.04 | L20: =CHOOSE($C$6,L22,L23,L24) -> 0.04
B22: Best Case | C22: 0.03 | H22: =H23+$C$22 -> 0.07 | I22: =I23+$C$22 -> 0.07 | J22: =J23+$C$22 -> 0.07 | K22: =K23+$C$22 -> 0.07 | L22: =L23+$C$22 -> 0.07
B23: Base Case | H23: 0.04 | I23: 0.04 | J23: 0.04 | K23: 0.04 | L23: 0.04
B24: Worst Case | C24: -0.03 | H24: =H23+$C$24 -> 0.01 | I24: =I23+$C$24 -> 0.01 | J24: =J23+$C$24 -> 0.01 | K24: =K23+$C$24 -> 0.01 | L24: =L23+$C$24 -> 0.01
B26: Transaction Expense | H26: =CHOOSE($C$6,H28,H29,H30) -> 0.0089 | I26: =CHOOSE($C$6,I28,I29,I30) -> 0.0089 | J26: =CHOOSE($C$6,J28,J29,J30) -> 0.0089 | K26: =CHOOSE($C$6,K28,K29,K30) -> 0.0089 | L26: =CHOOSE($C$6,L28,L29,L30) -> 0.0089
B28: Best Case | C28: -0.00025 | H28: =H29+$C$28 -> 0.00865 | I28: =I29+$C$28 -> 0.00865 | J28: =J29+$C$28 -> 0.00865 | K28: =K29+$C$28 -> 0.00865 | L28: =L29+$C$28 -> 0.00865
B29: Base Case | H29: 0.0089 | I29: 0.0089 | J29: 0.0089 | K29: 0.0089 | L29: 0.0089
B30: Worst Case | C30: 0.00025 | H30: =H29+$C$30 -> 0.00915 | I30: =I29+$C$30 -> 0.00915 | J30: =J29+$C$30 -> 0.00915 | K30: =K29+$C$30 -> 0.00915 | L30: =L29+$C$30 -> 0.00915
B32: Transaction and Credit Losses | H32: =CHOOSE($C$6,H34,H35,H36) -> 0.00096 | I32: =CHOOSE($C$6,I34,I35,I36) -> 0.00096 | J32: =CHOOSE($C$6,J34,J35,J36) -> 0.00096 | K32: =CHOOSE($C$6,K34,K35,K36) -> 0.00096 | L32: =CHOOSE($C$6,L34,L35,L36) -> 0.00096
B34: Best Case | C34: -0.0001 | H34: =H35+$C$34 -> 0.00086 | I34: =I35+$C$34 -> 0.00086 | J34: =J35+$C$34 -> 0.00086 | K34: =K35+$C$34 -> 0.00086 | L34: =L35+$C$34 -> 0.00086
B35: Base Case | H35: 0.00096 | I35: 0.00096 | J35: 0.00096 | K35: 0.00096 | L35: 0.00096
B36: Worst Case | C36: 0.0001 | H36: =H35+$C$36 -> 0.00106 | I36: =I35+$C$36 -> 0.00106 | J36: =J35+$C$36 -> 0.00106 | K36: =K35+$C$36 -> 0.00106 | L36: =L35+$C$36 -> 0.00106
B38: Technology and Development | H38: =CHOOSE($C$6,H40,H41,H42) -> 0.03 | I38: =CHOOSE($C$6,I40,I41,I42) -> 0.03 | J38: =CHOOSE($C$6,J40,J41,J42) -> 0.03 | K38: =CHOOSE($C$6,K40,K41,K42) -> 0.03 | L38: =CHOOSE($C$6,L40,L41,L42) -> 0.03
B40: Best Case | C40: -0.01 | H40: =H41+$C$40 -> 0.02 | I40: =I41+$C$40 -> 0.02 | J40: =J41+$C$40 -> 0.02 | K40: =K41+$C$40 -> 0.02 | L40: =L41+$C$40 -> 0.02
B41: Base Case | H41: 0.03 | I41: 0.03 | J41: 0.03 | K41: 0.03 | L41: 0.03
B42: Worst Case | C42: 0.01 | H42: =H41+$C$42 -> 0.04 | I42: =I41+$C$42 -> 0.04 | J42: =J41+$C$42 -> 0.04 | K42: =K41+$C$42 -> 0.04 | L42: =L41+$C$42 -> 0.04
B44: LBO Exit Multiple | H44: =CHOOSE($C$6,H46,H47,H48) -> 7 | I44: =CHOOSE($C$6,I46,I47,I48) -> 7 | J44: =CHOOSE($C$6,J46,J47,J48) -> 7 | K44: =CHOOSE($C$6,K46,K47,K48) -> 7 | L44: =CHOOSE($C$6,L46,L47,L48) -> 7
B46: Best Case | C46: 1 | H46: =H47+$C$46 -> 8 | I46: =I47+$C$46 -> 8 | J46: =J47+$C$46 -> 8 | K46: =K47+$C$46 -> 8 | L46: =L47+$C$46 -> 8
B47: Base Case | H47: 7 | I47: 7 | J47: 7 | K47: 7 | L47: 7
B48: Worst Case | C48: -1 | H48: =H47+$C$48 -> 6 | I48: =I47+$C$48 -> 6 | J48: =J47+$C$48 -> 6 | K48: =K47+$C$48 -> 6 | L48: =L47+$C$48 -> 6

Sheet Revenue Build
L1: ="CURRENTLY RUNNING: "&UPPER(CHOOSE(Scenarios!$C$6,Scenarios!B10,Scenarios!B11,Scenarios!B12))&" SCENARIO" -> CURRENTLY RUNNING: BASE CASE SCENARIO
B2: =Cover!$B$7 -> PayPal
B3: Revenue Build
B4: ($ Millions)
H5: Projected
E6: =F6-1 -> 2023 | F6: =G6-1 -> 2024 | G6: 2025 | H6: =G6+1 -> 2026 | I6: =H6+1 -> 2027 | J6: =I6+1 -> 2028 | K6: =J6+1 -> 2029 | L6: =K6+1 -> 2030
B8: Revenue by Service
C9: Transaction Revenue | E9: =E16 -> 26857 | F9: =F16 -> 28842 | G9: =G16 -> 29798 | H9: =H16 -> 30826.92 | I9: =I16 -> 32073.162 | J9: =J16 -> 33571.168 | K9: =K16 -> 35359.455 | L9: =L16 -> 37241.48
C10: Other Value-Added Services | E10: =E19 -> 2914 | F10: =F19 -> 2955 | G10: =G19 -> 3374 | H10: =H19 -> 3488.7661 | I10: =I19 -> 3615.7267 | J10: =J19 -> 3747.388 | K10: =K19 -> 3883.9267 | L10: =L19 -> 4025.5263
C11: Total | E11: =SUM(E9:E10) -> 29771 | F11: =SUM(F9:F10) -> 31797 | G11: =SUM(G9:G10) -> 33172 | H11: =SUM(H9:H10) -> 34315.686 | I11: =SUM(I9:I10) -> 35688.889 | J11: =SUM(J9:J10) -> 37318.556 | K11: =SUM(K9:K10) -> 39243.381 | L11: =SUM(L9:L10) -> 41267.006
B13: Transaction Revenue
C14: Total Payment Volume (TPV) | E14: 1527000 | F14: 1680000 | G14: 1790000 | H14: =G14*(1+Assumptions!N19) -> 1897400 | I14: =H14*(1+Scenarios!I8) -> 2011244 | J14: =I14*(1+Scenarios!J8) -> 2131918.6 | K14: =J14*(1+Scenarios!K8) -> 2259833.8 | L14: =K14*(1+Scenarios!L8) -> 2395423.8
C15: Take rate | E15: =E16/E14 -> 0.017588081 | F15: =F16/F14 -> 0.017167857 | G15: =G16/G14 -> 0.016646927 | H15: =G15+Scenarios!H14 -> 0.016246927 | I15: =H15+Scenarios!I14 -> 0.015946927 | J15: =I15+Scenarios!J14 -> 0.015746927 | K15: =J15+Scenarios!K14 -> 0.015646927 | L15: =K15+Scenarios!L14 -> 0.015546927
C16: Revenue | E16: 26857 | F16: 28842 | G16: 29798 | H16: =H14*H15 -> 30826.92 | I16: =I14*I15 -> 32073.162 | J16: =J14*J15 -> 33571.168 | K16: =K14*K15 -> 35359.455 | L16: =L14*L15 -> 37241.48
B18: Other Value-Added Services
C19: Total OVAS Revenue | E19: 2914 | F19: 2955 | G19: 3374 | H19: =H23+H24 -> 3488.7661 | I19: =I23+I24 -> 3615.7267 | J19: =J23+J24 -> 3747.388 | K19: =K23+K24 -> 3883.9267 | L19: =L23+L24 -> 4025.5263
C21: Customer funds balance | E21: 38935 | F21: 37671 | G21: 38198 | H21: =G21*(1+Assumptions!$N$32) -> 39343.94 | I21: =H21*(1+Assumptions!$N$32) -> 40524.258 | J21: =I21*(1+Assumptions!$N$32) -> 41739.986 | K21: =J21*(1+Assumptions!$N$32) -> 42992.186 | L21: =K21*(1+Assumptions!$N$32) -> 44281.951
C22: Effective yield | E22: =E23/E21 -> 0.023218184 | F22: =F23/F21 -> 0.034084574 | G22: =G23/G21 -> 0.032200639 | H22: =Assumptions!$N$31 -> 0.032 | I22: =Assumptions!$N$31 -> 0.032 | J22: =Assumptions!$N$31 -> 0.032 | K22: =Assumptions!$N$31 -> 0.032 | L22: =Assumptions!$N$31 -> 0.032
C23: Interest on customer balances | E23: 904 | F23: 1284 | G23: 1230 | H23: =H21*H22 -> 1259.0061 | I23: =I21*I22 -> 1296.7763 | J23: =J21*J22 -> 1335.6796 | K23: =K21*K22 -> 1375.7499 | L23: =L21*L22 -> 1417.0224
C24: Remaining OVAS, ex-interest | E24: =E19-E23 -> 2010 | F24: =F19-F23 -> 1671 | G24: =G19-G23 -> 2144 | H24: =G24*(1+Assumptions!$N$21) -> 2229.76 | I24: =H24*(1+Assumptions!$N$21) -> 2318.9504 | J24: =I24*(1+Assumptions!$N$21) -> 2411.7084 | K24: =J24*(1+Assumptions!$N$21) -> 2508.1768 | L24: =K24*(1+Assumptions!$N$21) -> 2608.5038

Sheet IS
L1: ="CURRENTLY RUNNING: "&UPPER(CHOOSE(Scenarios!$C$6,Scenarios!B10,Scenarios!B11,Scenarios!B12))&" SCENARIO" -> CURRENTLY RUNNING: BASE CASE SCENARIO
B2: =Cover!$B$7 -> PayPal
B3: Income Statement
B4: ($ Millions)
H5: Projected
E6: =F6-1 -> 2023 | F6: =G6-1 -> 2024 | G6: 2025 | H6: =G6+1 -> 2026 | I6: =H6+1 -> 2027 | J6: =I6+1 -> 2028 | K6: =J6+1 -> 2029 | L6: =K6+1 -> 2030
C8: Net Revenue | E8: 29771 | F8: 31797 | G8: 33172 | H8: ='Revenue Build'!H11 -> 34315.686 | I8: ='Revenue Build'!I11 -> 35688.889 | J8: ='Revenue Build'!J11 -> 37318.556 | K8: ='Revenue Build'!K11 -> 39243.381 | L8: ='Revenue Build'!L11 -> 41267.006
C9: Transaction Expense | E9: -14385 | F9: -15697 | G9: -15987 | H9: =-('Revenue Build'!H14*Assumptions!$H$28) -> -16886.86 | I9: =-('Revenue Build'!I14*Assumptions!$H$28) -> -17900.072 | J9: =-('Revenue Build'!J14*Assumptions!$H$28) -> -18974.076 | K9: =-('Revenue Build'!K14*Assumptions!$H$28) -> -20112.52 | L9: =-('Revenue Build'!L14*Assumptions!$H$28) -> -21319.272
C10: Transaction and Credit Losses | E10: -1682 | F10: -1442 | G10: -1720 | H10: =-('Revenue Build'!H14*Assumptions!$H$29) -> -1821.504 | I10: =-('Revenue Build'!I14*Assumptions!$H$29) -> -1930.7942 | J10: =-('Revenue Build'!J14*Assumptions!$H$29) -> -2046.6419 | K10: =-('Revenue Build'!K14*Assumptions!$H$29) -> -2169.4404 | L10: =-('Revenue Build'!L14*Assumptions!$H$29) -> -2299.6068
C11: Customer Support and Operations | E11: -1919 | F11: -1768 | G11: -1704 | H11: =-H8*Assumptions!$H$30 -> -1750.1 | I11: =-I8*Assumptions!$H$30 -> -1820.1333 | J11: =-J8*Assumptions!$H$30 -> -1903.2464 | K11: =-K8*Assumptions!$H$30 -> -2001.4125 | L11: =-L8*Assumptions!$H$30 -> -2104.6173
C12: Gross Profit | E12: =SUM(E8:E11) -> 11785 | F12: =SUM(F8:F11) -> 12890 | G12: =SUM(G8:G11) -> 13761 | H12: =SUM(H8:H11) -> 13857.222 | I12: =SUM(I8:I11) -> 14037.89 | J12: =SUM(J8:J11) -> 14394.592 | K12: =SUM(K8:K11) -> 14960.008 | L12: =SUM(L8:L11) -> 15543.51
C14: Sales and Marketing | E14: -1809 | F14: -2001 | G14: -2283 | H14: =-H8*Assumptions!$H$31 -> -2367.7823 | I14: =-I8*Assumptions!$H$31 -> -2462.5333 | J14: =-J8*Assumptions!$H$31 -> -2574.9804 | K14: =-K8*Assumptions!$H$31 -> -2707.7933 | L14: =-L8*Assumptions!$H$31 -> -2847.4234
C15: Technology and Development | E15: -2973 | F15: -2979 | G15: -3103 | H15: =G15*(1+Assumptions!$H$32) -> -3196.09 | I15: =H15*(1+Assumptions!$H$32) -> -3291.9727 | J15: =I15*(1+Assumptions!$H$32) -> -3390.7319 | K15: =J15*(1+Assumptions!$H$32) -> -3492.4538 | L15: =K15*(1+Assumptions!$H$32) -> -3597.2275
C16: General and Administrative | E16: -2059 | F16: -2147 | G16: -1979 | H16: =G16*(1+Assumptions!$H$33) -> -2018.58 | I16: =H16*(1+Assumptions!$H$33) -> -2058.9516 | J16: =I16*(1+Assumptions!$H$33) -> -2100.1306 | K16: =J16*(1+Assumptions!$H$33) -> -2142.1332 | L16: =K16*(1+Assumptions!$H$33) -> -2184.9759
C17: Restructuring and Other | E17: 84 | F17: -438 | G17: -331 | H17: 0 | I17: 0 | J17: 0 | K17: 0 | L17: 0
C18: EBIT | E18: =SUM(E12:E17) -> 5028 | F18: =SUM(F12:F17) -> 5325 | G18: =SUM(G12:G17) -> 6065 | H18: =SUM(H12:H17) -> 6274.7698 | I18: =SUM(I12:I17) -> 6224.4319 | J18: =SUM(J12:J17) -> 6328.7489 | K18: =SUM(K12:K17) -> 6617.6277 | L18: =SUM(L12:L17) -> 6913.8833
C20: Interest Income (Expense) | H20: ='Debt Schedule'!H39 -> -131.277 | I20: ='Debt Schedule'!I39 -> -88.34739 | J20: ='Debt Schedule'!J39 -> -50.059065 | K20: ='Debt Schedule'!K39 -> -8.3171577 | L20: ='Debt Schedule'!L39 -> 44.223401
C21: Other Income (expense), net | E21: 383 | F21: 4 | G21: 227 | H21: =AVERAGE($E$21:$G$21) -> 204.66667 | I21: =AVERAGE($E$21:$G$21) -> 204.66667 | J21: =AVERAGE($E$21:$G$21) -> 204.66667 | K21: =AVERAGE($E$21:$G$21) -> 204.66667 | L21: =AVERAGE($E$21:$G$21) -> 204.66667
C22: EBT | E22: =E21+E18 -> 5411 | F22: =F21+F18 -> 5329 | G22: =G21+G18 -> 6292 | H22: =H18+H21+H20 -> 6348.1594 | I22: =I18+I21+I20 -> 6340.7512 | J22: =J18+J21+J20 -> 6483.3565 | K22: =K18+K21+K20 -> 6813.9772 | L22: =L18+L21+L20 -> 7162.7734
C24: Income Tax Expense | E24: -1165 | F24: -1182 | G24: -1059 | H24: =-'Income Tax Schedule'!H17 -> -1092.7885 | I24: =-'Income Tax Schedule'!I17 -> -1172.0105 | J24: =-'Income Tax Schedule'!J17 -> -1255.5845 | K24: =-'Income Tax Schedule'!K17 -> -1360.6167 | L24: =-'Income Tax Schedule'!L17 -> -1457.4992
C25: Net Income | E25: =E22+E24 -> 4246 | F25: =F22+F24 -> 4147 | G25: =G22+G24 -> 5233 | H25: =H22+H24 -> 5255.3709 | I25: =I22+I24 -> 5168.7406 | J25: =J22+J24 -> 5227.7721 | K25: =K22+K24 -> 5453.3605 | L25: =L22+L24 -> 5705.2741
C27: Depreciation & Amortization | E27: -1072 | F27: -1032 | G27: -963 | H27: ='D&A Schedule'!G29 -> -872.06521 | I27: ='D&A Schedule'!H29 -> -879.8888 | J27: ='D&A Schedule'!I29 -> -916.67086 | K27: ='D&A Schedule'!J29 -> -927.60299 | L27: ='D&A Schedule'!K29 -> -990.2919
C28: EBITDA | E28: =E18-E27 -> 6100 | F28: =F18-F27 -> 6357 | G28: =G18-G27 -> 7028 | H28: =H18-H27 -> 7146.835 | I28: =I18-I27 -> 7104.3207 | J28: =J18-J27 -> 7245.4198 | K28: =K18-K27 -> 7545.2307 | L28: =L18-L27 -> 7904.1752
C30: Stock Based Compensation | E30: 1145 | F30: 1326 | G30: 1135 | H30: =H8*Assumptions!$H$34 -> 1166.7333 | I30: =I8*Assumptions!$H$34 -> 1213.4222 | J30: =J8*Assumptions!$H$34 -> 1268.8309 | K30: =K8*Assumptions!$H$34 -> 1334.275 | L30: =L8*Assumptions!$H$34 -> 1403.0782
C31: Adjusted EBITDA | H31: =H28+H30 -> 8313.5683 | I31: =I28+I30 -> 8317.7429 | J31: =J28+J30 -> 8514.2507 | K31: =K28+K30 -> 8879.5056 | L31: =L28+L30 -> 9307.2534
B33: Growth Rates & Margins
C34: Revenue Growth Rate | F34: =(F8/E8)-1 -> 0.068052803 | G34: =(G8/F8)-1 -> 0.043243073 | H34: =(H8/G8)-1 -> 0.034477453 | I34: =(I8/H8)-1 -> 0.04001676 | J34: =(J8/I8)-1 -> 0.045663156 | K34: =(K8/J8)-1 -> 0.05157824 | L34: =(L8/K8)-1 -> 0.051566007
C35: Transaction Expenses | E35: =-(E9/E8) -> 0.48318834 | F35: =-(F9/F8) -> 0.49366292 | G35: =-(G9/G8) -> 0.4819426 | H35: =-(H9/H8) -> 0.49210323 | I35: =-(I9/I8) -> 0.50155867 | J35: =-(J9/J8) -> 0.50843543 | K35: =-(K9/K8) -> 0.51250733 | L35: =-(L9/L8) -> 0.51661785
C36: Transaction & Credit Losses | E36: =-(E10/E8) -> 0.056497934 | F36: =-(F10/F8) -> 0.04535019 | G36: =-(G10/G8) -> 0.051850959 | H36: =-(H10/H8) -> 0.053080798 | I36: =-(I10/I8) -> 0.054100711 | J36: =-(J10/J8) -> 0.054842473 | K36: =-(K10/K8) -> 0.055281689 | L36: =-(L10/L8) -> 0.055725071
C37: Customer Support & Operations | F37: =(F11/E11)-1 -> -0.078686816 | G37: =(G11/F11)-1 -> -0.036199095 | H37: =(H11/G11)-1 -> 0.027053985 | I37: =(I11/H11)-1 -> 0.04001676 | J37: =(J11/I11)-1 -> 0.045663156 | K37: =(K11/J11)-1 -> 0.05157824 | L37: =(L11/K11)-1 -> 0.051566007
C38: Sales & Marketing | F38: =(F14/E14)-1 -> 0.10613599 | G38: =(G14/F14)-1 -> 0.14092954 | H38: =(H14/G14)-1 -> 0.037136373 | I38: =(I14/H14)-1 -> 0.04001676 | J38: =(J14/I14)-1 -> 0.045663156 | K38: =(K14/J14)-1 -> 0.05157824 | L38: =(L14/K14)-1 -> 0.051566007
C39: Technology & Development Growth | F39: =(F15/E15)-1 -> 0.0020181635 | G39: =(G15/F15)-1 -> 0.041624706 | H39: =(H15/G15)-1 -> 0.03 | I39: =(I15/H15)-1 -> 0.03 | J39: =(J15/I15)-1 -> 0.03 | K39: =(K15/J15)-1 -> 0.03 | L39: =(L15/K15)-1 -> 0.03
C40: General & Administrative | F40: =(F16/E16)-1 -> 0.042739194 | G40: =(G16/F16)-1 -> -0.078248719 | H40: =(H16/G16)-1 -> 0.02 | I40: =(I16/H16)-1 -> 0.02 | J40: =(J16/I16)-1 -> 0.02 | K40: =(K16/J16)-1 -> 0.02 | L40: =(L16/K16)-1 -> 0.02
C41: Stock-based compensation
C42: Gross Profit Margin | E42: =E12/E8 -> 0.39585503 | F42: =F12/F8 -> 0.40538416 | G42: =G12/G8 -> 0.41483782 | H42: =H12/H8 -> 0.40381597 | I42: =I12/I8 -> 0.39334062 | J42: =J12/J8 -> 0.3857221 | K42: =K12/K8 -> 0.38121099 | L42: =L12/L8 -> 0.37665708
C43: EBITDA Margin | E43: =E28/E8 -> 0.20489738 | F43: =F28/F8 -> 0.19992452 | G43: =G28/G8 -> 0.21186543 | H43: =H28/H8 -> 0.20826729 | I43: =I28/I8 -> 0.19906254 | J43: =J28/J8 -> 0.19415059 | K43: =K28/K8 -> 0.1922676 | L43: =L28/L8 -> 0.1915374
C44: EBIT Margin | E44: =E18/E8 -> 0.16888919 | F44: =F18/F8 -> 0.16746863 | G44: =G18/G8 -> 0.18283492 | H44: =H18/H8 -> 0.18285427 | I44: =I18/I8 -> 0.17440812 | J44: =J18/J8 -> 0.16958719 | K44: =K18/K8 -> 0.16863041 | L44: =L18/L8 -> 0.16754022
C45: Return on Equity | H45: =IS!H25/BS!H44 -> 0.24776892 | I45: =IS!I25/BS!I44 -> 0.23310461 | J45: =IS!J25/BS!J44 -> 0.22438236 | K45: =IS!K25/BS!K44 -> 0.22022729 | L45: =IS!L25/BS!L44 -> 0.21452488

Sheet BS
L1: ="CURRENTLY RUNNING: "&UPPER(CHOOSE(Scenarios!$C$6,Scenarios!B10,Scenarios!B11,Scenarios!B12))&" SCENARIO" -> CURRENTLY RUNNING: BASE CASE SCENARIO
B2: =Cover!$B$7 -> PayPal
B3: Balance Sheet
B4: ($ Millions)
H5: Projected
F6: =IS!F6 -> 2024 | G6: =IS!G6 -> 2025 | H6: =IS!H6 -> 2026 | I6: =IS!I6 -> 2027 | J6: =IS!J6 -> 2028 | K6: =IS!K6 -> 2029 | L6: =IS!L6 -> 2030
B8: Assets
C9: Cash & Equivalents | F9: =6662+4262 -> 10924 | G9: =8049+2373 -> 10422 | H9: ='Debt Schedule'!H11 -> 10036.887 | I9: ='Debt Schedule'!I11 -> 9915.6645 | J9: ='Debt Schedule'!J11 -> 9828.9614 | K9: ='Debt Schedule'!K11 -> 9630.3134 | L9: ='Debt Schedule'!L11 -> 10303.079
C10: Accounts Receivable, Net | F10: 984 | G10: 840 | H10: ='Working Capital Schedule'!H21 -> 864.94332 | I10: ='Working Capital Schedule'!I21 -> 899.55555 | J10: ='Working Capital Schedule'!J21 -> 938.06206 | K10: ='Working Capital Schedule'!K21 -> 989.14824 | L10: ='Working Capital Schedule'!L21 -> 1040.1547
C11: Inventory and Interest Receivable, Held for Sale | F11: 541 | G11: 1726 | H11: =(G11/IS!G8)*IS!H8 -> 1785.5081 | I11: =(H11/IS!H8)*IS!I8 -> 1856.9583 | J11: =(I11/IS!I8)*IS!J8 -> 1941.7529 | K11: =(J11/IS!J8)*IS!K8 -> 2041.9051 | L11: =(K11/IS!K8)*IS!L8 -> 2147.198
C12: Loans and Interest Receivable, Net of Allowances | F12: 6422 | G12: 6746 | H12: =G12*(IS!H8/IS!G8) -> 6978.5849 | I12: =H12*(IS!I8/IS!H8) -> 7257.8453 | J12: =I12*(IS!J8/IS!I8) -> 7589.2614 | K12: =J12*(IS!K8/IS!J8) -> 7980.7021 | L12: =K12*(IS!L8/IS!K8) -> 8392.2351
C13: Funds Receivable and Customer Accounts | F13: 37671 | G13: 38198 | H13: ='Working Capital Schedule'!H31 -> 39514.97 | I13: ='Working Capital Schedule'!I31 -> 41096.231 | J13: ='Working Capital Schedule'!J31 -> 42972.814 | K13: ='Working Capital Schedule'!K31 -> 45189.277 | L13: ='Working Capital Schedule'!L31 -> 47519.507
C14: Prepaid Expenses and Other Current Assets | F14: 1664 | G14: 1827 | H14: ='Working Capital Schedule'!H22 -> 1928.1402 | I14: ='Working Capital Schedule'!I22 -> 2040.5325 | J14: ='Working Capital Schedule'!J22 -> 2154.6021 | K14: ='Working Capital Schedule'!K22 -> 2288.6248 | L14: ='Working Capital Schedule'!L22 -> 2424.3514
C15: Total Current Assets | F15: =SUM(F9:F14) -> 58206 | G15: =SUM(G9:G14) -> 59759 | H15: =SUM(H9:H14) -> 61109.033 | I15: =SUM(I9:I14) -> 63066.787 | J15: =SUM(J9:J14) -> 65425.454 | K15: =SUM(K9:K14) -> 68119.97 | L15: =SUM(L9:L14) -> 71826.525
C17: Long-Term Investments | F17: 4583 | G17: 4330 | H17: =G17 -> 4330 | I17: =H17 -> 4330 | J17: =I17 -> 4330 | K17: =J17 -> 4330 | L17: =K17 -> 4330
C18: Property and Equipment, Net | F18: 1508 | G18: 1700 | H18: ='D&A Schedule'!G25 -> 1749.5113 | I18: ='D&A Schedule'!H25 -> 1788.1558 | J18: ='D&A Schedule'!I25 -> 1815.1303 | K18: ='D&A Schedule'!J25 -> 1829.3684 | L18: ='D&A Schedule'!K25 -> 1829.4847
C19: Goodwill | F19: 10837 | G19: 10864 | H19: =G19 -> 10864 | I19: =H19 -> 10864 | J19: =I19 -> 10864 | K19: =J19 -> 10864 | L19: =K19 -> 10864
C20: Intangible Assets, Net | F20: 326 | G20: 208 | H20: ='D&A Schedule'!G11 -> 110 | I20: ='D&A Schedule'!H11 -> 48 | J20: ='D&A Schedule'!I11 -> 0 | K20: ='D&A Schedule'!J11 -> 0 | L20: ='D&A Schedule'!K11 -> 0
C21: Other Assets | F21: 3265 | G21: 3312 | H21: =(G21/IS!G8)*IS!H8 -> 3426.1893 | I21: =(H21/IS!H8)*IS!I8 -> 3563.2943 | J21: =(I21/IS!I8)*IS!J8 -> 3726.0056 | K21: =(J21/IS!J8)*IS!K8 -> 3918.1864 | L21: =(K21/IS!K8)*IS!L8 -> 4120.2316
C22: Total Long Term Assets | F22: =SUM(F17:F21) -> 20519 | G22: =SUM(G17:G21) -> 20414 | H22: =SUM(H17:H21) -> 20479.701 | I22: =SUM(I17:I21) -> 20593.45 | J22: =SUM(J17:J21) -> 20735.136 | K22: =SUM(K17:K21) -> 20941.555 | L22: =SUM(L17:L21) -> 21143.716
C24: Total Assets | F24: =+F15+F22 -> 78725 | G24: =+G15+G22 -> 80173 | H24: =+H15+H22 -> 81588.734 | I24: =+I15+I22 -> 83660.237 | J24: =+J15+J22 -> 86160.59 | K24: =+K15+K22 -> 89061.525 | L24: =+L15+L22 -> 92970.242
B27: Liabilities and Equity
C28: Accounts Payable | F28: 227 | G28: 240 | H28: ='Working Capital Schedule'!H23 -> 252.22764 | I28: ='Working Capital Schedule'!I23 -> 266.93013 | J28: ='Working Capital Schedule'!J23 -> 281.85202 | K28: ='Working Capital Schedule'!K23 -> 299.38405 | L28: ='Working Capital Schedule'!L23 -> 317.13899
C29: Funds Payable to Customers | F29: 39671 | G29: 40198 | H29: =-'Working Capital Schedule'!H32 -> 41583.925 | I29: =-'Working Capital Schedule'!I32 -> 43247.979 | J29: =-'Working Capital Schedule'!J32 -> 45222.818 | K29: =-'Working Capital Schedule'!K32 -> 47555.331 | L29: =-'Working Capital Schedule'!L32 -> 50007.57
C30: Accrued Expenses and Other Current Liabilities | F30: =5592-1191 -> 4401 | G30: =6005-1396 -> 4609 | H30: ='Working Capital Schedule'!H24 -> 4859.5858 | I30: ='Working Capital Schedule'!I24 -> 5142.8538 | J30: ='Working Capital Schedule'!J24 -> 5430.3489 | K30: ='Working Capital Schedule'!K24 -> 5768.1328 | L30: ='Working Capital Schedule'!L24 -> 6110.2112
C31: Current Portion of Term Debt | F31: 1191 | G31: 1396
C32: Total Current Liabilities | F32: =SUM(F28:F31) -> 45490 | G32: =SUM(G28:G31) -> 46443 | H32: =SUM(H28:H31) -> 46695.738 | I32: =SUM(I28:I31) -> 48657.763 | J32: =SUM(J28:J31) -> 50935.019 | K32: =SUM(K28:K31) -> 53622.848 | L32: =SUM(L28:L31) -> 56434.92
C34: Other Long-Term Liabilities | F34: 2939 | G34: 3487 | H34: =G34*(1+Assumptions!$N$19) -> 3696.22 | I34: =H34*(1+Assumptions!$N$19) -> 3917.9932 | J34: =I34*(1+Assumptions!$N$19) -> 4153.0728 | K34: =J34*(1+Assumptions!$N$19) -> 4402.2572 | L34: =K34*(1+Assumptions!$N$19) -> 4666.3926
C35: Long-Term Debt | F35: 9879 | G35: 9987 | H35: ='Debt Schedule'!H34 -> 9986 | I35: ='Debt Schedule'!I34 -> 8911 | J35: ='Debt Schedule'!J34 -> 7774 | K35: ='Debt Schedule'!K34 -> 6274 | L35: ='Debt Schedule'!L34 -> 5274
C36: Total Long Term Liabilities | F36: =SUM(F34:F35) -> 12818 | G36: =SUM(G34:G35) -> 13474 | H36: =SUM(H34:H35) -> 13682.22 | I36: =SUM(I34:I35) -> 12828.993 | J36: =SUM(J34:J35) -> 11927.073 | K36: =SUM(K34:K35) -> 10676.257 | L36: =SUM(L34:L35) -> 9940.3926
C38: Total Liabilities | F38: =F36+F32 -> 58308 | G38: =G36+G32 -> 59917 | H38: =H36+H32 -> 60377.958 | I38: =I36+I32 -> 61486.756 | J38: =J36+J32 -> 62862.092 | K38: =K36+K32 -> 64299.105 | L38: =L36+L32 -> 66375.312
C40: Treasury Stock | F40: -27085 | G40: -33138 | H40: =G40-(Assumptions!$N$10*'Equity Schedule'!H9) -> -38138 | I40: =H40-(Assumptions!$N$10*'Equity Schedule'!I9) -> -43138 | J40: =I40-(Assumptions!$N$10*'Equity Schedule'!J9) -> -48138 | K40: =J40-(Assumptions!$N$10*'Equity Schedule'!K9) -> -53138 | L40: =K40-(Assumptions!$N$10*'Equity Schedule'!L9) -> -58138
C41: Additional Paid-In-Capital | F41: 20705 | G41: 21582 | H41: =G41+IS!H30 -> 22748.733 | I41: =H41+IS!I30 -> 23962.156 | J41: =I41+IS!J30 -> 25230.986 | K41: =J41+IS!K30 -> 26565.261 | L41: =K41+IS!L30 -> 27968.34
C42: Retained Earnings | F42: 27347 | G42: 32470 | H42: ='Equity Schedule'!H19 -> 37258.042 | I42: ='Equity Schedule'!I19 -> 42007.326 | J42: ='Equity Schedule'!J19 -> 46863.512 | K42: ='Equity Schedule'!K19 -> 51993.158 | L42: ='Equity Schedule'!L19 -> 57422.59
C43: Accumulated Other Comprhensive Income (Loss) | F43: -550 | G43: -658 | H43: =G43 -> -658 | I43: =H43 -> -658 | J43: =I43 -> -658 | K43: =J43 -> -658 | L43: =K43 -> -658
C44: Shareholder's Equity | F44: =SUM(F40:F43) -> 20417 | G44: =SUM(G40:G43) -> 20256 | H44: =SUM(H40:H43) -> 21210.776 | I44: =SUM(I40:I43) -> 22173.481 | J44: =SUM(J40:J43) -> 23298.499 | K44: =SUM(K40:K43) -> 24762.42 | L44: =SUM(L40:L43) -> 26594.929
B46: Total Liabilities and Equity | F46: =F44+F38 -> 78725 | G46: =G44+G38 -> 80173 | H46: =H44+H38 -> 81588.734 | I46: =I44+I38 -> 83660.237 | J46: =J44+J38 -> 86160.59 | K46: =K44+K38 -> 89061.525 | L46: =L44+L38 -> 92970.242
D48: Check | F48: =ROUND(F24-F46,3) -> 0 | G48: =ROUND(G24-G46,3) -> 0 | H48: =ROUND(H24-H46,3) -> 0 | I48: =ROUND(I24-I46,3) -> 0 | J48: =ROUND(J24-J46,3) -> 0 | K48: =ROUND(K24-K46,3) -> 0 | L48: =ROUND(L24-L46,3) -> 0

Sheet CFS
L1: ="CURRENTLY RUNNING: "&UPPER(CHOOSE(Scenarios!$C$6,Scenarios!B10,Scenarios!B11,Scenarios!B12))&" SCENARIO" -> CURRENTLY RUNNING: BASE CASE SCENARIO
B2: =Cover!$B$7 -> PayPal
B3: Cash Flow Statement
B4: ($ Millions)
H5: Projected
H6: =IS!H6 -> 2026 | I6: =IS!I6 -> 2027 | J6: =IS!J6 -> 2028 | K6: =IS!K6 -> 2029 | L6: =IS!L6 -> 2030
B7: Operating Activities
C8: Net Income | H8: =IS!H25 -> 5255.3709 | I8: =IS!I25 -> 5168.7406 | J8: =IS!J25 -> 5227.7721 | K8: =IS!K25 -> 5453.3605 | L8: =IS!L25 -> 5705.2741
C9: Depreciation & Amortization | H9: =-'D&A Schedule'!G29 -> 872.06521 | I9: =-'D&A Schedule'!H29 -> 879.8888 | J9: =-'D&A Schedule'!I29 -> 916.67086 | K9: =-'D&A Schedule'!J29 -> 927.60299 | L9: =-'D&A Schedule'!K29 -> 990.2919
C10: Stock Based Compensation | H10: =IS!H30 -> 1166.7333 | I10: =IS!I30 -> 1213.4222 | J10: =IS!J30 -> 1268.8309 | K10: =IS!K30 -> 1334.275 | L10: =IS!L30 -> 1403.0782
C11: Adjustments to Loans and Interest Receivable, Held for Sale | H11: =BS!G11-BS!H11 -> -59.508084 | I11: =BS!H11-BS!I11 -> -71.450249 | J11: =BS!I11-BS!J11 -> -84.794578 | K11: =BS!J11-BS!K11 -> -100.1522 | L11: =BS!K11-BS!L11 -> -105.29289
C12: Accounts Receivable | H12: =BS!G10-BS!H10 -> -24.94332 | I12: =BS!H10-BS!I10 -> -34.612229 | J12: =BS!I10-BS!J10 -> -38.506512 | K12: =BS!J10-BS!K10 -> -51.086181 | L12: =BS!K10-BS!L10 -> -51.006425
C13: Other Current Assest and Non-Current Assets | H13: =(BS!G14-BS!H14)+(BS!G21-BS!H21) -> -215.32949 | I13: =(BS!H14-BS!I14)+(BS!H21-BS!I21) -> -249.49735 | J13: =(BS!I14-BS!J14)+(BS!I21-BS!J21) -> -276.78084 | K13: =(BS!J14-BS!K14)+(BS!J21-BS!K21) -> -326.20349 | L13: =(BS!K14-BS!L14)+(BS!K21-BS!L21) -> -337.77184
C14: Accounts Payable | H14: =BS!H28-BS!G28 -> 12.227638 | I14: =BS!I28-BS!H28 -> 14.702488 | J14: =BS!J28-BS!I28 -> 14.921892 | K14: =BS!K28-BS!J28 -> 17.532036 | L14: =BS!L28-BS!K28 -> 17.754935
C15: Other Current Liabilities and Non-Current Liabilities | H15: =(BS!H30-BS!G30)+(BS!H34-BS!G34) -> 459.80583 | I15: =(BS!I30-BS!H30)+(BS!I34-BS!H34) -> 505.04114 | J15: =(BS!J30-BS!I30)+(BS!J34-BS!I34) -> 522.5747 | K15: =(BS!K30-BS!J30)+(BS!K34-BS!J34) -> 586.96827 | L15: =(BS!L30-BS!K30)+(BS!L34-BS!K34) -> 606.21384
C16: Operating Cash Flow | H16: =SUM(H8:H15) -> 7466.422 | I16: =SUM(I8:I15) -> 7426.2354 | J16: =SUM(J8:J15) -> 7550.6885 | K16: =SUM(K8:K15) -> 7842.2969 | L16: =SUM(L8:L15) -> 8228.5418
B18: Investing Activities
C19: Purchases of Property and Equipment | H19: =-('D&A Schedule'!G22) -> -823.57647 | I19: =-('D&A Schedule'!H22) -> -856.53333 | J19: =-('D&A Schedule'!I22) -> -895.64534 | K19: =-('D&A Schedule'!J22) -> -941.84115 | L19: =-('D&A Schedule'!K22) -> -990.40814
C20: Net Loan & Investment Forecast | H20: =(BS!G12-BS!H12)+(BS!G13-BS!H13) -> -1549.5547 | I20: =(BS!H12-BS!I12)+(BS!H13-BS!I13) -> -1860.5214 | J20: =(BS!I12-BS!J12)+(BS!I13-BS!J13) -> -2207.9997 | K20: =(BS!J12-BS!K12)+(BS!J13-BS!K13) -> -2607.9029 | L20: =(BS!K12-BS!L12)+(BS!K13-BS!L13) -> -2741.7635
C21: Investing Cash Flow | H21: =SUM(H19:H20) -> -2373.1311 | I21: =SUM(I19:I20) -> -2717.0548 | J21: =SUM(J19:J20) -> -3103.6451 | K21: =SUM(K19:K20) -> -3549.744 | L21: =SUM(L19:L20) -> -3732.1716
B23: Financing Activities
C24: Purchases of treasury stock | H24: =-('Equity Schedule'!H9*Assumptions!$N$10) -> -5000 | I24: =-('Equity Schedule'!I9*Assumptions!$N$10) -> -5000 | J24: =-('Equity Schedule'!J9*Assumptions!$N$10) -> -5000 | K24: =-('Equity Schedule'!K9*Assumptions!$N$10) -> -5000 | L24: =-('Equity Schedule'!L9*Assumptions!$N$10) -> -5000
C25: Repayments under financing arrangements | H25: ='Debt Schedule'!H19 -> -1397 | I25: ='Debt Schedule'!I19 -> -1075 | J25: ='Debt Schedule'!J19 -> -1137 | K25: ='Debt Schedule'!K19 -> -1500 | L25: ='Debt Schedule'!L19 -> -1000
C26: Common Dividends | H26: =-('Equity Schedule'!H13) -> -467.32857 | I26: =-('Equity Schedule'!I13) -> -419.45714 | J26: =-('Equity Schedule'!J13) -> -371.58571 | K26: =-('Equity Schedule'!K13) -> -323.71428 | L26: =-('Equity Schedule'!L13) -> -275.84284
C27: Net Float & Financing , Forecast | H27: =BS!H29-BS!G29 -> 1385.9247 | I27: =BS!I29-BS!H29 -> 1664.0539 | J27: =BS!J29-BS!I29 -> 1974.8392 | K27: =BS!K29-BS!J29 -> 2332.5133 | L27: =BS!L29-BS!K29 -> 2452.2385
C28: Financing Cash Flow | H28: =SUM(H24:H27) -> -5478.4039 | I28: =SUM(I24:I27) -> -4830.4032 | J28: =SUM(J24:J27) -> -4533.7465 | K28: =SUM(K24:K27) -> -4491.2009 | L28: =SUM(L24:L27) -> -3823.6043
B31: Change in the Cash Position | H31: =H28+H21+H16 -> -385.113 | I31: =I28+I21+I16 -> -121.2225 | J31: =J28+J21+J16 -> -86.703086 | K31: =K28+K21+K16 -> -198.64803 | L31: =L28+L21+L16 -> 672.76588
B32: Beginning Cash | H32: =BS!G9 -> 10422 | I32: =+H33 -> 10036.887 | J32: =+I33 -> 9915.6645 | K32: =+J33 -> 9828.9614 | L32: =+K33 -> 9630.3134
B33: Ending Cash | H33: =H32+H31 -> 10036.887 | I33: =I32+I31 -> 9915.6645 | J33: =J32+J31 -> 9828.9614 | K33: =K32+K31 -> 9630.3134 | L33: =L32+L31 -> 10303.079

Sheet Working Capital Schedule
L1: ="CURRENTLY RUNNING: "&UPPER(CHOOSE(Scenarios!$C$6,Scenarios!B10,Scenarios!B11,Scenarios!B12))&" SCENARIO" -> CURRENTLY RUNNING: BASE CASE SCENARIO
B2: PayPal
B3: Working Capital Schedule
B4: ($ Millions)
H5: Projected
E6: =IS!E6 -> 2023 | F6: =IS!F6 -> 2024 | G6: =IS!G6 -> 2025 | H6: =IS!H6 -> 2026 | I6: =IS!I6 -> 2027 | J6: =IS!J6 -> 2028 | K6: =IS!K6 -> 2029 | L6: =IS!L6 -> 2030
B8: Days per Year | F8: =DATE(F6,12,31)-DATE(E6,12,31) -> 366 | G8: =DATE(G6,12,31)-DATE(F6,12,31) -> 365 | H8: =DATE(H6,12,31)-DATE(G6,12,31) -> 365 | I8: =DATE(I6,12,31)-DATE(H6,12,31) -> 365 | J8: =DATE(J6,12,31)-DATE(I6,12,31) -> 366 | K8: =DATE(K6,12,31)-DATE(J6,12,31) -> 365 | L8: =DATE(L6,12,31)-DATE(K6,12,31) -> 365
B10: Income Statement Items
C11: Net Revenue | F11: =IS!F8 -> 31797 | G11: =IS!G8 -> 33172 | H11: =IS!H8 -> 34315.686 | I11: =IS!I8 -> 35688.889 | J11: =IS!J8 -> 37318.556 | K11: =IS!K8 -> 39243.381 | L11: =IS!L8 -> 41267.006
C12: Cost of Sales | F12: =-(IS!F9+IS!F10+IS!F11) -> 18907 | G12: =-(IS!G9+IS!G10+IS!G11) -> 19411 | H12: =-(IS!H9+IS!H10+IS!H11) -> 20458.464 | I12: =-(IS!I9+IS!I10+IS!I11) -> 21650.999 | J12: =-(IS!J9+IS!J10+IS!J11) -> 22923.964 | K12: =-(IS!K9+IS!K10+IS!K11) -> 24283.373 | L12: =-(IS!L9+IS!L10+IS!L11) -> 25723.496
B14: Days In
C15: Accounts Receivable (days) | F15: =F21/F11*F8 -> 11.326352 | G15: =G21/G11*G8 -> 9.2427348 | H15: =Assumptions!J68 -> 9.2 | I15: =Assumptions!K68 -> 9.2 | J15: =Assumptions!L68 -> 9.2 | K15: =Assumptions!M68 -> 9.2 | L15: =Assumptions!N68 -> 9.2
C16: Prepaid Expenses (days) | F16: =F22/F12*F8 -> 32.211562 | G16: =G22/G12*G8 -> 34.35449 | H16: =Assumptions!J69 -> 34.4 | I16: =Assumptions!K69 -> 34.4 | J16: =Assumptions!L69 -> 34.4 | K16: =Assumptions!M69 -> 34.4 | L16: =Assumptions!N69 -> 34.4
C17: Accounts Payable (days) | F17: =F23/F12*F8 -> 4.3942455 | G17: =G23/G12*G8 -> 4.5129051 | H17: =Assumptions!J70 -> 4.5 | I17: =Assumptions!K70 -> 4.5 | J17: =Assumptions!L70 -> 4.5 | K17: =Assumptions!M70 -> 4.5 | L17: =Assumptions!N70 -> 4.5
C18: Other Liabilities (days) | F18: =F24/F12*F8 -> 85.194161 | G18: =G24/G12*G8 -> 86.666581 | H18: =Assumptions!J71 -> 86.7 | I18: =Assumptions!K71 -> 86.7 | J18: =Assumptions!L71 -> 86.7 | K18: =Assumptions!M71 -> 86.7 | L18: =Assumptions!N71 -> 86.7
B20: Account Balances
C21: Accounts Receivable | F21: 984 | G21: 840 | H21: =H11/H8*H15 -> 864.94332 | I21: =I11/I8*I15 -> 899.55555 | J21: =J11/J8*J15 -> 938.06206 | K21: =K11/K8*K15 -> 989.14824 | L21: =L11/L8*L15 -> 1040.1547
C22: Prepaid Expenses | F22: 1664 | G22: 1827 | H22: =H12/H8*H16 -> 1928.1402 | I22: =I12/I8*I16 -> 2040.5325 | J22: =J12/J8*J16 -> 2154.6021 | K22: =K12/K8*K16 -> 2288.6248 | L22: =L12/L8*L16 -> 2424.3514
C23: Accounts Payable | F23: 227 | G23: 240 | H23: =H12/H8*H17 -> 252.22764 | I23: =I12/I8*I17 -> 266.93013 | J23: =J12/J8*J17 -> 281.85202 | K23: =K12/K8*K17 -> 299.38405 | L23: =L12/L8*L17 -> 317.13899
C24: Accrued Expenses and Other Current Liabilities | F24: 4401 | G24: 4609 | H24: =H12/H8*H18 -> 4859.5858 | I24: =I12/I8*I18 -> 5142.8538 | J24: =J12/J8*J18 -> 5430.3489 | K24: =K12/K8*K18 -> 5768.1328 | L24: =L12/L8*L18 -> 6110.2112
C25: Net Working Capital | F25: =SUM(F21:F22)-SUM(F23:F24) -> -1980 | G25: =SUM(G21:G22)-SUM(G23:G24) -> -2182 | H25: =SUM(H21:H22)-SUM(H23:H24) -> -2318.73 | I25: =SUM(I21:I22)-SUM(I23:I24) -> -2469.6958 | J25: =SUM(J21:J22)-SUM(J23:J24) -> -2619.5367 | K25: =SUM(K21:K22)-SUM(K23:K24) -> -2789.7438 | L25: =SUM(L21:L22)-SUM(L23:L24) -> -2962.8441
B27: Change in Working Capital | G27: =F25-G25 -> 202 | H27: =G25-H25 -> 136.72998 | I27: =H25-I25 -> 150.96585 | J27: =I25-J25 -> 149.84092 | K27: =J25-K25 -> 170.20708 | L27: =K25-L25 -> 173.10031
B29: Custodial Float
C31: Funds Receivable and Customer Accounts | F31: 37671 | G31: 38198 | H31: =G31*(IS!H8/IS!G8) -> 39514.97 | I31: =H31*(IS!I8/IS!H8) -> 41096.231 | J31: =I31*(IS!J8/IS!I8) -> 42972.814 | K31: =J31*(IS!K8/IS!J8) -> 45189.277 | L31: =K31*(IS!L8/IS!K8) -> 47519.507
C32: Funds Payable to Customers | F32: -39671 | G32: -40198 | H32: =G32*(IS!H8/IS!G8) -> -41583.925 | I32: =H32*(IS!I8/IS!H8) -> -43247.979 | J32: =I32*(IS!J8/IS!I8) -> -45222.818 | K32: =J32*(IS!K8/IS!J8) -> -47555.331 | L32: =K32*(IS!L8/IS!K8) -> -50007.57
C33: Net Float | F33: =F31+F32 -> -2000 | G33: =G31+G32 -> -2000 | H33: =H31+H32 -> -2068.9549 | I33: =I31+I32 -> -2151.7478 | J33: =J31+J32 -> -2250.0034 | K33: =K31+K32 -> -2366.0546 | L33: =L31+L32 -> -2488.0626

Sheet D&A Schedule
K1: ="CURRENTLY RUNNING: "&UPPER(CHOOSE(Scenarios!$C$6,Scenarios!B10,Scenarios!B11,Scenarios!B12))&" SCENARIO" -> CURRENTLY RUNNING: BASE CASE SCENARIO
B2: =Cover!$B$7 -> PayPal
B3: Intangible Assets
B4: ($ Millions)
G5: Projected
E6: =IS!F6 -> 2024 | F6: =IS!G6 -> 2025 | G6: =IS!H6 -> 2026 | H6: =IS!I6 -> 2027 | I6: =IS!J6 -> 2028 | J6: =IS!K6 -> 2029 | K6: =IS!L6 -> 2030
B8: Beginning of Period | E8: 533 | F8: =E11 -> 326 | G8: =F11 -> 208 | H8: =G11 -> 110 | I8: =H11 -> 48 | J8: =I11 -> 0 | K8: =J11 -> 0
C9: Less: Amortization | E9: -207 | F9: -175 | G9: -98 | H9: -62 | I9: -48
C10: Other/Non-Cash | E10: 0 | F10: 57 | G10: 0 | H10: 0 | I10: 0 | J10: 0 | K10: 0
C11: End of Period | E11: 326 | F11: =SUM(F8:F10) -> 208 | G11: =SUM(G8:G10) -> 110 | H11: =SUM(H8:H10) -> 48 | I11: =SUM(I8:I10) -> 0 | J11: =SUM(J8:J10) -> 0 | K11: =SUM(K8:K10) -> 0
B15: =Cover!$B$7 -> PayPal
B16: Property, Plant, & Equipment
B17: ($ Millions)
G18: Projected
E19: =E6 -> 2024 | F19: =F6 -> 2025 | G19: =CFS!H6 -> 2026 | H19: =CFS!I6 -> 2027 | I19: =CFS!J6 -> 2028 | J19: =CFS!K6 -> 2029 | K19: =CFS!L6 -> 2030
B21: Beginning of Period | F21: =E25 -> 1508 | G21: =F25 -> 1700 | H21: =G25 -> 1749.5113 | I21: =H25 -> 1788.1558 | J21: =I25 -> 1815.1303 | K21: =J25 -> 1829.3684
C22: Plus: Capital Expenditure | E22: 683 | F22: 852 | G22: =Assumptions!J59 -> 823.57647 | H22: =Assumptions!K59 -> 856.53333 | I22: =Assumptions!L59 -> 895.64534 | J22: =Assumptions!M59 -> 941.84115 | K22: =Assumptions!N59 -> 990.40814
C23: Less: Depreciation | E23: -825 | F23: -788 | G23: =-G22*G27 -> -774.06521 | H23: =-H22*H27 -> -817.8888 | I23: =-I22*I27 -> -868.67086 | J23: =-J22*J27 -> -927.60299 | K23: =-K22*K27 -> -990.2919
C24: Non-Cash Additions/ Other | F24: 128
C25: End of Period | E25: =BS!F18 -> 1508 | F25: =BS!G18 -> 1700 | G25: =SUM(G21:G24) -> 1749.5113 | H25: =SUM(H21:H24) -> 1788.1558 | I25: =SUM(I21:I24) -> 1815.1303 | J25: =SUM(J21:J24) -> 1829.3684 | K25: =SUM(K21:K24) -> 1829.4847
C27: PP&E related D&A as % of capex | D27: 0.015 | E27: =-(E23/E22) -> 1.2079063 | F27: =-(F23/F22) -> 0.92488263 | G27: =F27+$D$27 -> 0.93988263 | H27: =G27+$D$27 -> 0.95488263 | I27: =H27+$D$27 -> 0.96988263 | J27: =I27+$D$27 -> 0.98488263 | K27: =J27+$D$27 -> 0.99988263
B29: Total D&A | E29: =E23+E9 -> -1032 | F29: =F23+F9 -> -963 | G29: =G23+G9 -> -872.06521 | H29: =H23+H9 -> -879.8888 | I29: =I23+I9 -> -916.67086 | J29: =J23+J9 -> -927.60299 | K29: =K23+K9 -> -990.2919

Sheet Debt Schedule
L1: ="CURRENTLY RUNNING: "&UPPER(CHOOSE(Scenarios!$C$6,Scenarios!B10,Scenarios!B11,Scenarios!B12))&" SCENARIO" -> CURRENTLY RUNNING: BASE CASE SCENARIO
B2: =Cover!$B$7 -> PayPal
B3: Debt and Interest Schedule
B4: ($ Millions)
H5: Projected
G6: ='D&A Schedule'!F19 -> 2025 | H6: ='Income Tax Schedule'!H6 -> 2026 | I6: ='Income Tax Schedule'!I6 -> 2027 | J6: ='Income Tax Schedule'!J6 -> 2028 | K6: ='Income Tax Schedule'!K6 -> 2029 | L6: ='Income Tax Schedule'!L6 -> 2030
B7: Financing Component
C8: Cash
C9: Amount Outstanding - Beginning | H9: =G11 -> 10422 | I9: =H11 -> 10036.887 | J9: =I11 -> 9915.6645 | K9: =J11 -> 9828.9614 | L9: =K11 -> 9630.3134
C10: Change in Cash | H10: =CFS!H31 -> -385.113 | I10: =CFS!I31 -> -121.2225 | J10: =CFS!J31 -> -86.703086 | K10: =CFS!K31 -> -198.64803 | L10: =CFS!L31 -> 672.76588
C11: Amount Outstanding - Ending | G11: =BS!G9 -> 10422 | H11: =SUM(H9:H10) -> 10036.887 | I11: =SUM(I9:I10) -> 9915.6645 | J11: =SUM(J9:J10) -> 9828.9614 | K11: =SUM(K9:K10) -> 9630.3134 | L11: =SUM(L9:L10) -> 10303.079
C13: Interest Rate | H13: =Assumptions!N28 -> 0.03 | I13: =H13 -> 0.03 | J13: =I13 -> 0.03 | K13: =J13 -> 0.03 | L13: =K13 -> 0.03
C14: Annual Interest Income | H14: =H13*H9 -> 312.66 | I14: =I13*I9 -> 301.10661 | J14: =J13*J9 -> 297.46993 | K14: =K13*K9 -> 294.86884 | L14: =L13*L9 -> 288.9094
C16: Revolver
C17: Operating Cash Flow | H17: =CFS!H16 -> 7466.422 | I17: =CFS!I16 -> 7426.2354 | J17: =CFS!J16 -> 7550.6885 | K17: =CFS!K16 -> 7842.2969 | L17: =CFS!L16 -> 8228.5418
C18: Investing Cash Flow | H18: =CFS!H21 -> -2373.1311 | I18: =CFS!I21 -> -2717.0548 | J18: =CFS!J21 -> -3103.6451 | K18: =CFS!K21 -> -3549.744 | L18: =CFS!L21 -> -3732.1716
C19: Mandatory Debt Repayments | H19: =H33 -> -1397 | I19: =I33 -> -1075 | J19: =J33 -> -1137 | K19: =K33 -> -1500 | L19: =L33 -> -1000
C20: Common Stock Issuance / (Buy-back) | H20: =IS!G269 -> 0 | I20: =IS!H269 -> 0 | J20: =IS!I269 -> 0 | K20: =IS!J269 -> 0 | L20: =IS!K269 -> 0
C21: Dividends | I21: =BS!H31 -> 0 | J21: =BS!I31 -> 0 | K21: =BS!J31 -> 0 | L21: =BS!K31 -> 0
C22: FCF After Mandatory Debt Repayment and Dividend | H22: =SUM(H17:H21) -> 3696.2909 | I22: =SUM(I17:I21) -> 3634.1807 | J22: =SUM(J17:J21) -> 3310.0434 | K22: =SUM(K17:K21) -> 2792.5529 | L22: =SUM(L17:L21) -> 3496.3702
C24: Revolver Outstanding - Beginning | H24: =G26 -> 0 | I24: =H26 -> 0 | J24: =I26 -> 0 | K24: =J26 -> 0 | L24: =K26 -> 0
C25: Additions / (Repayments) | H25: =-MIN((H22+H9),H24) -> 0 | I25: =-MIN((I22+I9),I24) -> 0 | J25: =-MIN((J22+J9),J24) -> 0 | K25: =-MIN((K22+K9),K24) -> 0 | L25: =-MIN((L22+L9),L24) -> 0
C26: Revolver Outstanding - Ending | G26: 0 | H26: =SUM(H24:H25) -> 0 | I26: =SUM(I24:I25) -> 0 | J26: =SUM(J24:J25) -> 0 | K26: =SUM(K24:K25) -> 0 | L26: =SUM(L24:L25) -> 0
C28: Interest Rate | H28: 0.045 | I28: =H28 -> 0.045 | J28: =I28 -> 0.045 | K28: =J28 -> 0.045 | L28: =K28 -> 0.045
C29: Annual Interest Expense | H29: =H28*H24 -> 0 | I29: =I28*I24 -> 0 | J29: =J28*J24 -> 0 | K29: =K28*K24 -> 0 | L29: =L28*L24 -> 0
C31: Term Debt
C32: Amount Outstanding - Beginning | H32: =G34 -> 11383 | I32: =H34 -> 9986 | J32: =I34 -> 8911 | K32: =J34 -> 7774 | L32: =K34 -> 6274
C33: Additions / (Repayments) | H33: =-Assumptions!H45 -> -1397 | I33: =-Assumptions!H46 -> -1075 | J33: =-Assumptions!H47 -> -1137 | K33: =-Assumptions!H48 -> -1500 | L33: =-Assumptions!H49 -> -1000
C34: Amount Outstanding - Ending | G34: =BS!G35+BS!G31 -> 11383 | H34: =SUM(H32:H33) -> 9986 | I34: =SUM(I32:I33) -> 8911 | J34: =SUM(J32:J33) -> 7774 | K34: =SUM(K32:K33) -> 6274 | L34: =SUM(L32:L33) -> 5274
C36: Interest Rate | H36: =Assumptions!N30 -> 0.039 | I36: =H36 -> 0.039 | J36: =I36 -> 0.039 | K36: =J36 -> 0.039 | L36: =K36 -> 0.039
C37: Annual Interest Expense | H37: =H36*H32 -> 443.937 | I37: =I36*I32 -> 389.454 | J37: =J36*J32 -> 347.529 | K37: =K36*K32 -> 303.186 | L37: =L36*L32 -> 244.686
C39: Net Interest Expense | H39: =H14-H37 -> -131.277 | I39: =I14-I37 -> -88.34739 | J39: =J14-J37 -> -50.059065 | K39: =K14-K37 -> -8.3171577 | L39: =L14-L37 -> 44.223401

Sheet Income Tax Schedule
L1: ="CURRENTLY RUNNING: "&UPPER(CHOOSE(Scenarios!$C$6,Scenarios!B10,Scenarios!B11,Scenarios!B12))&" SCENARIO" -> CURRENTLY RUNNING: BASE CASE SCENARIO
B2: =Cover!$B$7 -> PayPal
B3: Income Tax Schedule
B4: ($ Millions)
H5: Projected
C6: Tax Rate | E6: 0.21 | H6: ='D&A Schedule'!G19 -> 2026 | I6: ='D&A Schedule'!H19 -> 2027 | J6: ='D&A Schedule'!I19 -> 2028 | K6: ='D&A Schedule'!J19 -> 2029 | L6: ='D&A Schedule'!K19 -> 2030
C9: Accounting EBT (as is on I/S) | G9: A | H9: =IS!H22 -> 6348.1594 | I9: =IS!I22 -> 6340.7512 | J9: =IS!J22 -> 6483.3565 | K9: =IS!K22 -> 6813.9772 | L9: =IS!L22 -> 7162.7734
C11: Less: Reduction in EBT for timing differences | H11: =Assumptions!J62 -> 1144.4047 | I11: =Assumptions!K62 -> 759.74868 | J11: =Assumptions!L62 -> 504.38283 | K11: =Assumptions!M62 -> 334.85025 | L11: =Assumptions!N62 -> 222.30077
C12: Government EBT | G12: B | H12: =H9-H11 -> 5203.7548 | I12: =I9-I11 -> 5581.0025 | J12: =J9-J11 -> 5978.9737 | K12: =K9-K11 -> 6479.1269 | L12: =L9-L11 -> 6940.4726
C14: =CONCATENATE("Accounting Taxes (",$E$6*100,"% of A)") -> Accounting Taxes (21% of A) | H14: =$E$6*H9 -> 1333.1135 | I14: =$E$6*I9 -> 1331.5577 | J14: =$E$6*J9 -> 1361.5049 | K14: =$E$6*K9 -> 1430.9352 | L14: =$E$6*L9 -> 1504.1824
C16: Taxes as Appearing on Income Statement
C17: =CONCATENATE("Current Tax (",$E$6*100,"% of B)") -> Current Tax (21% of B) | H17: =$E$6*H12 -> 1092.7885 | I17: =$E$6*I12 -> 1172.0105 | J17: =$E$6*J12 -> 1255.5845 | K17: =$E$6*K12 -> 1360.6167 | L17: =$E$6*L12 -> 1457.4992
C18: Increase (Decrease) in Deferred Income Taxes | H18: =H14-H17 -> 240.32498 | I18: =I14-I17 -> 159.54722 | J18: =J14-J17 -> 105.92039 | K18: =K14-K17 -> 70.318553 | L18: =L14-L17 -> 46.683162
C19: Total Income Taxes (Same as Accounting Taxes Above) | H19: =SUM(H17:H18) -> 1333.1135 | I19: =SUM(I17:I18) -> 1331.5577 | J19: =SUM(J17:J18) -> 1361.5049 | K19: =SUM(K17:K18) -> 1430.9352 | L19: =SUM(L17:L18) -> 1504.1824

Sheet Equity Schedule
L1: ="CURRENTLY RUNNING: "&UPPER(CHOOSE(Scenarios!$C$6,Scenarios!B10,Scenarios!B11,Scenarios!B12))&" SCENARIO" -> CURRENTLY RUNNING: BASE CASE SCENARIO
B2: =Cover!$B$7 -> PayPal
B3: Equity Schedule
B4: ($ Millions)
H5: Projected
G6: ='D&A Schedule'!F19 -> 2025 | H6: ='Income Tax Schedule'!H6 -> 2026 | I6: ='Income Tax Schedule'!I6 -> 2027 | J6: ='Income Tax Schedule'!J6 -> 2028 | K6: ='Income Tax Schedule'!K6 -> 2029 | L6: ='Income Tax Schedule'!L6 -> 2030
B7: Common Shares
C8: Amount Outstanding - Beginning | H8: =G10 -> 920 | I8: =H10 -> 834.5153 | J8: =I10 -> 749.0306 | K8: =J10 -> 663.54591 | L8: =K10 -> 578.06121
C9: New Issuance / (Buy-Back) | H9: =5000000000/Assumptions!$N$10/1000000 -> 85.484698 | I9: =5000000000/Assumptions!$N$10/1000000 -> 85.484698 | J9: =5000000000/Assumptions!$N$10/1000000 -> 85.484698 | K9: =5000000000/Assumptions!$N$10/1000000 -> 85.484698 | L9: =5000000000/Assumptions!$N$10/1000000 -> 85.484698
C10: Amount Outstanding - Ending | G10: 920 | H10: =H8-H9 -> 834.5153 | I10: =I8-I9 -> 749.0306 | J10: =J8-J9 -> 663.54591 | K10: =K8-K9 -> 578.06121 | L10: =L8-L9 -> 492.57651
C12: Dividend/ Share | H12: 0.56 | I12: =H12 -> 0.56 | J12: =I12 -> 0.56 | K12: =J12 -> 0.56 | L12: =K12 -> 0.56
C13: Common Dividend | H13: =H12*H10 -> 467.32857 | I13: =I12*I10 -> 419.45714 | J13: =J12*J10 -> 371.58571 | K13: =K12*K10 -> 323.71428 | L13: =L12*L10 -> 275.84284
B15: Retained Earnings
C16: Amount Outstanding - Beginning | H16: =G19 -> 32470 | I16: =H19 -> 37258.042 | J16: =I19 -> 42007.326 | K16: =J19 -> 46863.512 | L16: =K19 -> 51993.158
C17: Net Income | H17: =IS!H25 -> 5255.3709 | I17: =IS!I25 -> 5168.7406 | J17: =IS!J25 -> 5227.7721 | K17: =IS!K25 -> 5453.3605 | L17: =IS!L25 -> 5705.2741
C18: Common Dividend | H18: =-H13 -> -467.32857 | I18: =-I13 -> -419.45714 | J18: =-J13 -> -371.58571 | K18: =-K13 -> -323.71428 | L18: =-L13 -> -275.84284
C19: Amount Outstanding - Ending | G19: =BS!G42 -> 32470 | H19: =SUM(H16:H18) -> 37258.042 | I19: =SUM(I16:I18) -> 42007.326 | J19: =SUM(J16:J18) -> 46863.512 | K19: =SUM(K16:K18) -> 51993.158 | L19: =SUM(L16:L18) -> 57422.59
H21: Projected
G22: =G6 -> 2025 | H22: =H6 -> 2026 | I22: =I6 -> 2027 | J22: =J6 -> 2028 | K22: =K6 -> 2029 | L22: =L6 -> 2030
B24: Earnings Per Share
C25: Net Income | G25: =IS!G25 -> 5233 | H25: =IS!H25 -> 5255.3709 | I25: =IS!I25 -> 5168.7406 | J25: =IS!J25 -> 5227.7721 | K25: =IS!K25 -> 5453.3605 | L25: =IS!L25 -> 5705.2741
C26: Basic Shares | G26: =Assumptions!N9 -> 920.664 | H26: =(H10+H8)/2 -> 877.25765 | I26: =(I10+I8)/2 -> 791.77295 | J26: =(J10+J8)/2 -> 706.28825 | K26: =(K10+K8)/2 -> 620.80356 | L26: =(L10+L8)/2 -> 535.31886
C27: Basic EPS | G27: =G25/G26 -> 5.6839412 | H27: =H25/H26 -> 5.9906812 | I27: =I25/I26 -> 6.5280591 | J27: =J25/J26 -> 7.4017542 | K27: =K25/K26 -> 8.7843578 | L27: =L25/L26 -> 10.657712
C29: Diluted Shares | G29: =G26+Assumptions!N11 -> 952.421 | H29: =(G29-G26)+H26 -> 909.01465 | I29: =(H29-H26)+I26 -> 823.52995 | J29: =(I29-I26)+J26 -> 738.04525 | K29: =(J29-J26)+K26 -> 652.56056 | L29: =(K29-K26)+L26 -> 567.07586
C30: Diluted EPS | G30: =G25/G29 -> 5.494419 | H30: =H25/H29 -> 5.781393 | I30: =I25/I29 -> 6.2763238 | J30: =J25/J29 -> 7.0832676 | K30: =K25/K29 -> 8.3568651 | L30: =L25/L29 -> 10.060866
C32: $ amount of shares repurchased | H32: =H9*Assumptions!$N$10 -> 5000 | I32: =I9*Assumptions!$N$10 -> 5000 | J32: =J9*Assumptions!$N$10 -> 5000 | K32: =K9*Assumptions!$N$10 -> 5000 | L32: =L9*Assumptions!$N$10 -> 5000
C33: $ amount of new shares issued | H33: =IS!H30 -> 1166.7333 | I33: =IS!I30 -> 1213.4222 | J33: =IS!J30 -> 1268.8309 | K33: =IS!K30 -> 1334.275 | L33: =IS!L30 -> 1403.0782
C34: Target P/E | H34: 8 | I34: 8 | J34: 8 | K34: 8 | L34: 8
C35: Avg price (share count only) | H35: =(H25/G26)*H34 -> 45.665919 | I35: =(I25/H26)*I34 -> 47.13544 | J35: =(J25/I26)*J34 -> 52.820921 | K35: =(K25/J26)*K34 -> 61.769234 | L35: =(L25/K26)*L34 -> 73.521152

Sheet DCF
I1: ="CURRENTLY RUNNING: "&UPPER(CHOOSE(Scenarios!$C$6,Scenarios!B10,Scenarios!B11,Scenarios!B12))&" SCENARIO" -> CURRENTLY RUNNING: BASE CASE SCENARIO
B2: =Cover!B7 -> PayPal
B3: Discounted Cash Flow Analysis
B4: ($ Millions)
B6: Most recent fiscal year end | C6: 46022 | G6: Discount rate (WACC) | I6: =E53 -> 0.095880549
B7: End of first fiscal year | C7: 46387 | G7: Share price | I7: =Assumptions!N7 -> 45.47
B8: Most recent quarter end date | G8: Share price date | I8: =Assumptions!N8 -> 46208
B9: Valuation date | C9: 46204 | G9: Midyear adjustment? | I9: 0
B10: Portion of First Year Cash Flows | C10: =1-YEARFRAC(C9,C7) -> 0.5
B12: Unlevered Free Cash Flows | E12: Projected
B13: Fiscal year | D13: ='Equity Schedule'!G6 -> 2025 | E13: ='Equity Schedule'!H6 -> 2026 | F13: ='Equity Schedule'!I6 -> 2027 | G13: ='Equity Schedule'!J6 -> 2028 | H13: ='Equity Schedule'!K6 -> 2029 | I13: ='Equity Schedule'!L6 -> 2030
B14: Year Ended | D14: =C6 -> 46022 | E14: =EOMONTH(D14,12) -> 46387 | F14: =EOMONTH(E14,12) -> 46752 | G14: =EOMONTH(F14,12) -> 47118 | H14: =EOMONTH(G14,12) -> 47483 | I14: =EOMONTH(H14,12) -> 47848
B16: Revenue | D16: =IS!G8 -> 33172 | E16: =IS!H8 -> 34315.686 | F16: =IS!I8 -> 35688.889 | G16: =IS!J8 -> 37318.556 | H16: =IS!K8 -> 39243.381 | I16: =IS!L8 -> 41267.006
B17: % growth | E17: =E16/D16-1 -> 0.034477453 | F17: =F16/E16-1 -> 0.04001676 | G17: =G16/F16-1 -> 0.045663156 | H17: =H16/G16-1 -> 0.05157824 | I17: =I16/H16-1 -> 0.051566007
B18: EBITDA | D18: =IS!G28 -> 7028 | E18: =IS!H28 -> 7146.835 | F18: =IS!I28 -> 7104.3207 | G18: =IS!J28 -> 7245.4198 | H18: =IS!K28 -> 7545.2307 | I18: =IS!L28 -> 7904.1752
